import {
  ConflictException,
  InternalServerErrorException,
} from '@nestjs/common';
import { EntityRepository, Repository } from 'typeorm';
import * as bcrypt from 'bcrypt';
import { AuthCredentailsDto } from './dto/auth-credentials.dto';
import { User } from './user.entity';

@EntityRepository(User)
export class UserRepository extends Repository<User> {
  async signUp(authCredentialsDto: AuthCredentailsDto): Promise<void> {
    const { username, password } = authCredentialsDto;

    const user = new User();
    user.username = username;
    user.salt = await bcrypt.genSalt();
    user.password = await this.hashPassword(password, user.salt);

    console.log(user.password);

    try {
      await user.save();
    } catch (error) {
      if (error.code == 23505) {
        throw new ConflictException('Username already exist');
      } else {
        throw new InternalServerErrorException();
      }
    }
  }

  async validateUserPassword(
    authCredentialsDto: AuthCredentailsDto,
  ): Promise<string> {
    const { username, password } = authCredentialsDto;
    const user = await this.findOne({ username });
    if (user && (await user.validatePassword(password))) {
      return user.username;
    }
    return null;
  }

  private async hashPassword(password: string, salt: string): Promise<string> {
    return bcrypt.hash(password, salt);
  }
}
